2024-10-29 21:24:54,344 DEBUG    root            Loaded Command Group: ['gcloud', 'container', 'clusters']
2024-10-29 21:24:54,345 DEBUG    root            Loaded Command Group: ['gcloud', 'container', 'clusters', 'get_credentials']
2024-10-29 21:24:54,368 DEBUG    root            Running [gcloud.container.clusters.get-credentials] with arguments: [NAME: "k8-hello-world"]
2024-10-29 21:24:54,370 INFO     ___FILE_ONLY___ Fetching cluster endpoint and auth data.

2024-10-29 21:24:54,372 DEBUG    urllib3.connectionpool Starting new HTTPS connection (1): container.googleapis.com:443
2024-10-29 21:24:54,755 DEBUG    urllib3.connectionpool https://container.googleapis.com:443 "GET /v1/projects/practica5-1234/locations/europe-west1-b/clusters/k8-hello-world?alt=json HTTP/1.1" 404 None
2024-10-29 21:24:54,758 DEBUG    urllib3.connectionpool Starting new HTTPS connection (1): container.googleapis.com:443
2024-10-29 21:24:55,471 DEBUG    urllib3.connectionpool https://container.googleapis.com:443 "GET /v1/projects/practica5-1234/locations/-/clusters?alt=json HTTP/1.1" 200 None
2024-10-29 21:24:55,472 DEBUG    root            (gcloud.container.clusters.get-credentials) ResponseError: code=404, message=Not found: projects/practica5-1234/zones/europe-west1-b/clusters/k8-hello-world. This command is authenticated as jdiazderabago@gmail.com which is the active account specified by the [core/account] property.
No cluster named 'k8-hello-world' in practica5-1234.
Traceback (most recent call last):
  File "/usr/bin/../lib/google-cloud-sdk/lib/googlecloudsdk/api_lib/container/api_adapter.py", line 1803, in GetCluster
    return self.client.projects_locations_clusters.Get(
           ^^^^^^^^^^^^^^^^^^^^^^^^^^^^^^^^^^^^^^^^^^^^
  File "/usr/bin/../lib/google-cloud-sdk/lib/googlecloudsdk/generated_clients/apis/container/v1/container_v1_client.py", line 628, in Get
    return self._RunMethod(
           ^^^^^^^^^^^^^^^^
  File "/usr/bin/../lib/google-cloud-sdk/lib/third_party/apitools/base/py/base_api.py", line 747, in _RunMethod
    return self.ProcessHttpResponse(method_config, http_response, request)
           ^^^^^^^^^^^^^^^^^^^^^^^^^^^^^^^^^^^^^^^^^^^^^^^^^^^^^^^^^^^^^^^
  File "/usr/bin/../lib/google-cloud-sdk/lib/third_party/apitools/base/py/base_api.py", line 753, in ProcessHttpResponse
    self.__ProcessHttpResponse(method_config, http_response, request))
    ^^^^^^^^^^^^^^^^^^^^^^^^^^^^^^^^^^^^^^^^^^^^^^^^^^^^^^^^^^^^^^^^^
  File "/usr/bin/../lib/google-cloud-sdk/lib/third_party/apitools/base/py/base_api.py", line 612, in __ProcessHttpResponse
    raise exceptions.HttpError.FromResponse(
apitools.base.py.exceptions.HttpNotFoundError: HttpError accessing <https://container.googleapis.com/v1/projects/practica5-1234/locations/europe-west1-b/clusters/k8-hello-world?alt=json>: response: <{'vary': 'Origin, X-Origin, Referer', 'content-type': 'application/json; charset=UTF-8', 'content-encoding': 'gzip', 'date': 'Tue, 29 Oct 2024 20:24:54 GMT', 'server': 'ESF', 'cache-control': 'private', 'x-xss-protection': '0', 'x-frame-options': 'SAMEORIGIN', 'x-content-type-options': 'nosniff', 'alt-svc': 'h3=":443"; ma=2592000,h3-29=":443"; ma=2592000', 'transfer-encoding': 'chunked', 'status': 404}>, content <{
  "error": {
    "code": 404,
    "message": "Not found: projects/practica5-1234/zones/europe-west1-b/clusters/k8-hello-world.",
    "status": "NOT_FOUND",
    "details": [
      {
        "@type": "type.googleapis.com/google.rpc.RequestInfo",
        "requestId": "0x67477b8c87ce0ac"
      }
    ]
  }
}
>

During handling of the above exception, another exception occurred:

Traceback (most recent call last):
  File "/usr/bin/../lib/google-cloud-sdk/lib/googlecloudsdk/calliope/cli.py", line 998, in Execute
    resources = calliope_command.Run(cli=self, args=args)
                ^^^^^^^^^^^^^^^^^^^^^^^^^^^^^^^^^^^^^^^^^
  File "/usr/bin/../lib/google-cloud-sdk/lib/googlecloudsdk/calliope/backend.py", line 842, in Run
    resources = command_instance.Run(args)
                ^^^^^^^^^^^^^^^^^^^^^^^^^^
  File "/usr/bin/../lib/google-cloud-sdk/lib/surface/container/clusters/get_credentials.py", line 119, in Run
    cluster, cluster_ref = _BaseRun(args, self.context)
                           ^^^^^^^^^^^^^^^^^^^^^^^^^^^^
  File "/usr/bin/../lib/google-cloud-sdk/lib/surface/container/clusters/get_credentials.py", line 41, in _BaseRun
    cluster = adapter.GetCluster(cluster_ref)
              ^^^^^^^^^^^^^^^^^^^^^^^^^^^^^^^
  File "/usr/bin/../lib/google-cloud-sdk/lib/googlecloudsdk/api_lib/container/api_adapter.py", line 1810, in GetCluster
    self.CheckClusterOtherZones(cluster_ref, api_error)
  File "/usr/bin/../lib/google-cloud-sdk/lib/googlecloudsdk/api_lib/container/api_adapter.py", line 1906, in CheckClusterOtherZones
    raise not_found_error
googlecloudsdk.api_lib.container.util.Error: ResponseError: code=404, message=Not found: projects/practica5-1234/zones/europe-west1-b/clusters/k8-hello-world. This command is authenticated as jdiazderabago@gmail.com which is the active account specified by the [core/account] property.
No cluster named 'k8-hello-world' in practica5-1234.
2024-10-29 21:24:55,474 ERROR    root            (gcloud.container.clusters.get-credentials) ResponseError: code=404, message=Not found: projects/practica5-1234/zones/europe-west1-b/clusters/k8-hello-world. This command is authenticated as jdiazderabago@gmail.com which is the active account specified by the [core/account] property.
No cluster named 'k8-hello-world' in practica5-1234.
