2024-10-29 22:45:28,974 DEBUG    root            Loaded Command Group: ['gcloud', 'container', 'clusters']
2024-10-29 22:45:28,977 DEBUG    root            Loaded Command Group: ['gcloud', 'container', 'clusters', 'create']
2024-10-29 22:45:29,008 DEBUG    root            Running [gcloud.container.clusters.create] with arguments: [--enable-vertical-pod-autoscaling: "True", --num-nodes: "3", --release-channel: "['rapid']", NAME: "scaling-demo"]
2024-10-29 22:45:29,011 INFO     ___FILE_ONLY___ Note: The Kubelet readonly port (10255) is now deprecated. Please update your workloads to use the recommended alternatives. See https://cloud.google.com/kubernetes-engine/docs/how-to/disable-kubelet-readonly-port for ways to check usage and for migration instructions.

2024-10-29 22:45:29,011 INFO     ___FILE_ONLY___ Note: Your Pod address range (`--cluster-ipv4-cidr`) can accommodate at most 1008 node(s).

2024-10-29 22:45:29,013 DEBUG    urllib3.connectionpool Starting new HTTPS connection (1): container.googleapis.com:443
2024-10-29 22:45:29,370 DEBUG    urllib3.connectionpool https://container.googleapis.com:443 "POST /v1/projects/practica5-1234/locations/europe-west1-b/clusters?alt=json HTTP/1.1" 409 None
2024-10-29 22:45:29,374 DEBUG    root            (gcloud.container.clusters.create) ResponseError: code=409, message=Already exists: projects/practica5-1234/zones/europe-west1-b/clusters/scaling-demo.
Traceback (most recent call last):
  File "/usr/bin/../lib/google-cloud-sdk/lib/surface/container/clusters/create.py", line 1260, in Run
    operation_ref = adapter.CreateCluster(cluster_ref, options)
                    ^^^^^^^^^^^^^^^^^^^^^^^^^^^^^^^^^^^^^^^^^^^
  File "/usr/bin/../lib/google-cloud-sdk/lib/googlecloudsdk/api_lib/container/api_adapter.py", line 3390, in CreateCluster
    operation = self.client.projects_locations_clusters.Create(req)
                ^^^^^^^^^^^^^^^^^^^^^^^^^^^^^^^^^^^^^^^^^^^^^^^^^^^
  File "/usr/bin/../lib/google-cloud-sdk/lib/googlecloudsdk/generated_clients/apis/container/v1/container_v1_client.py", line 547, in Create
    return self._RunMethod(
           ^^^^^^^^^^^^^^^^
  File "/usr/bin/../lib/google-cloud-sdk/lib/third_party/apitools/base/py/base_api.py", line 747, in _RunMethod
    return self.ProcessHttpResponse(method_config, http_response, request)
           ^^^^^^^^^^^^^^^^^^^^^^^^^^^^^^^^^^^^^^^^^^^^^^^^^^^^^^^^^^^^^^^
  File "/usr/bin/../lib/google-cloud-sdk/lib/third_party/apitools/base/py/base_api.py", line 753, in ProcessHttpResponse
    self.__ProcessHttpResponse(method_config, http_response, request))
    ^^^^^^^^^^^^^^^^^^^^^^^^^^^^^^^^^^^^^^^^^^^^^^^^^^^^^^^^^^^^^^^^^
  File "/usr/bin/../lib/google-cloud-sdk/lib/third_party/apitools/base/py/base_api.py", line 612, in __ProcessHttpResponse
    raise exceptions.HttpError.FromResponse(
apitools.base.py.exceptions.HttpConflictError: HttpError accessing <https://container.googleapis.com/v1/projects/practica5-1234/locations/europe-west1-b/clusters?alt=json>: response: <{'vary': 'Origin, X-Origin, Referer', 'content-type': 'application/json; charset=UTF-8', 'content-encoding': 'gzip', 'date': 'Tue, 29 Oct 2024 21:45:29 GMT', 'server': 'ESF', 'cache-control': 'private', 'x-xss-protection': '0', 'x-frame-options': 'SAMEORIGIN', 'x-content-type-options': 'nosniff', 'alt-svc': 'h3=":443"; ma=2592000,h3-29=":443"; ma=2592000', 'transfer-encoding': 'chunked', 'status': 409}>, content <{
  "error": {
    "code": 409,
    "message": "Already exists: projects/practica5-1234/zones/europe-west1-b/clusters/scaling-demo.",
    "status": "ALREADY_EXISTS",
    "details": [
      {
        "@type": "type.googleapis.com/google.rpc.RequestInfo",
        "requestId": "0xe662e4190e14dca5"
      }
    ]
  }
}
>

During handling of the above exception, another exception occurred:

Traceback (most recent call last):
  File "/usr/bin/../lib/google-cloud-sdk/lib/googlecloudsdk/calliope/cli.py", line 998, in Execute
    resources = calliope_command.Run(cli=self, args=args)
                ^^^^^^^^^^^^^^^^^^^^^^^^^^^^^^^^^^^^^^^^^
  File "/usr/bin/../lib/google-cloud-sdk/lib/googlecloudsdk/calliope/backend.py", line 842, in Run
    resources = command_instance.Run(args)
                ^^^^^^^^^^^^^^^^^^^^^^^^^^
  File "/usr/bin/../lib/google-cloud-sdk/lib/surface/container/clusters/create.py", line 1271, in Run
    raise exceptions.HttpException(error, util.HTTP_ERROR_FORMAT)
googlecloudsdk.calliope.exceptions.HttpException: ResponseError: code=409, message=Already exists: projects/practica5-1234/zones/europe-west1-b/clusters/scaling-demo.
2024-10-29 22:45:29,377 ERROR    root            (gcloud.container.clusters.create) ResponseError: code=409, message=Already exists: projects/practica5-1234/zones/europe-west1-b/clusters/scaling-demo.
