2024-11-04 15:54:25,814 DEBUG    root            Loaded Command Group: ['gcloud', 'services']
2024-11-04 15:54:25,816 DEBUG    root            Loaded Command Group: ['gcloud', 'services', 'enable']
2024-11-04 15:54:25,818 DEBUG    root            Running [gcloud.services.enable] with arguments: [SERVICE:5: "[' cloudbuild.googleapis.com', ' compute.googleapis.com', ' container.googleapis.com', ' containeranalysis.googleapis.com', ' containerregistry.googleapis.com']"]
2024-11-04 15:54:25,854 DEBUG    urllib3.connectionpool Starting new HTTPS connection (1): serviceusage.googleapis.com:443
2024-11-04 15:54:26,643 DEBUG    urllib3.connectionpool https://serviceusage.googleapis.com:443 "POST /v1/projects/proyectotest-1/services:batchEnable?alt=json HTTP/1.1" 403 None
2024-11-04 15:54:26,644 DEBUG    root            Chosen display Format:default
2024-11-04 15:54:26,654 DEBUG    root            Chosen display Format:default
2024-11-04 15:54:26,653 DEBUG    root            (gcloud.services.enable) [jdiazderabago@gmail.com] does not have permission to access projects instance [proyectotest-1] (or it may not exist): Not found or permission denied for service(s):  cloudbuild.googleapis.com.
Help Token: AYJSUtllWNq0pi3pqHVwTZJvqGLdXto6DeLqY7kTSpxt2rCCwCuapye6l0QQEH0WL9E3WfYpSHAfsc0qW41B-7W-BKyi-gN9LCH_hhjm5WmFt-b0. This command is authenticated as jdiazderabago@gmail.com which is the active account specified by the [core/account] property
- '@type': type.googleapis.com/google.rpc.PreconditionFailure
  violations:
  - subject: ?error_code=220002&services=+cloudbuild.googleapis.com
    type: googleapis.com
- '@type': type.googleapis.com/google.rpc.ErrorInfo
  domain: serviceusage.googleapis.com
  metadata:
    services: ' cloudbuild.googleapis.com'
  reason: SERVICE_CONFIG_NOT_FOUND_OR_PERMISSION_DENIED
Traceback (most recent call last):
  File "/usr/bin/../lib/google-cloud-sdk/lib/googlecloudsdk/api_lib/services/serviceusage.py", line 695, in BatchEnableApiCall
    return client.services.BatchEnable(request)
           ^^^^^^^^^^^^^^^^^^^^^^^^^^^^^^^^^^^^
  File "/usr/bin/../lib/google-cloud-sdk/lib/googlecloudsdk/generated_clients/apis/serviceusage/v1/serviceusage_v1_client.py", line 182, in BatchEnable
    return self._RunMethod(
           ^^^^^^^^^^^^^^^^
  File "/usr/bin/../lib/google-cloud-sdk/lib/third_party/apitools/base/py/base_api.py", line 747, in _RunMethod
    return self.ProcessHttpResponse(method_config, http_response, request)
           ^^^^^^^^^^^^^^^^^^^^^^^^^^^^^^^^^^^^^^^^^^^^^^^^^^^^^^^^^^^^^^^
  File "/usr/bin/../lib/google-cloud-sdk/lib/third_party/apitools/base/py/base_api.py", line 753, in ProcessHttpResponse
    self.__ProcessHttpResponse(method_config, http_response, request))
    ^^^^^^^^^^^^^^^^^^^^^^^^^^^^^^^^^^^^^^^^^^^^^^^^^^^^^^^^^^^^^^^^^
  File "/usr/bin/../lib/google-cloud-sdk/lib/third_party/apitools/base/py/base_api.py", line 612, in __ProcessHttpResponse
    raise exceptions.HttpError.FromResponse(
apitools.base.py.exceptions.HttpForbiddenError: HttpError accessing <https://serviceusage.googleapis.com/v1/projects/proyectotest-1/services:batchEnable?alt=json>: response: <{'vary': 'Origin, X-Origin, Referer', 'content-type': 'application/json; charset=UTF-8', 'content-encoding': 'gzip', 'date': 'Mon, 04 Nov 2024 14:54:26 GMT', 'server': 'ESF', 'cache-control': 'private', 'x-xss-protection': '0', 'x-frame-options': 'SAMEORIGIN', 'x-content-type-options': 'nosniff', 'alt-svc': 'h3=":443"; ma=2592000,h3-29=":443"; ma=2592000', 'transfer-encoding': 'chunked', 'status': 403}>, content <{
  "error": {
    "code": 403,
    "message": "Not found or permission denied for service(s):  cloudbuild.googleapis.com.\nHelp Token: AYJSUtllWNq0pi3pqHVwTZJvqGLdXto6DeLqY7kTSpxt2rCCwCuapye6l0QQEH0WL9E3WfYpSHAfsc0qW41B-7W-BKyi-gN9LCH_hhjm5WmFt-b0",
    "status": "PERMISSION_DENIED",
    "details": [
      {
        "@type": "type.googleapis.com/google.rpc.PreconditionFailure",
        "violations": [
          {
            "type": "googleapis.com",
            "subject": "?error_code=220002&services=+cloudbuild.googleapis.com"
          }
        ]
      },
      {
        "@type": "type.googleapis.com/google.rpc.ErrorInfo",
        "reason": "SERVICE_CONFIG_NOT_FOUND_OR_PERMISSION_DENIED",
        "domain": "serviceusage.googleapis.com",
        "metadata": {
          "services": " cloudbuild.googleapis.com"
        }
      }
    ]
  }
}
>

During handling of the above exception, another exception occurred:

Traceback (most recent call last):
  File "/usr/bin/../lib/google-cloud-sdk/lib/googlecloudsdk/calliope/cli.py", line 998, in Execute
    resources = calliope_command.Run(cli=self, args=args)
                ^^^^^^^^^^^^^^^^^^^^^^^^^^^^^^^^^^^^^^^^^
  File "/usr/bin/../lib/google-cloud-sdk/lib/googlecloudsdk/calliope/backend.py", line 842, in Run
    resources = command_instance.Run(args)
                ^^^^^^^^^^^^^^^^^^^^^^^^^^
  File "/usr/bin/../lib/google-cloud-sdk/lib/surface/services/enable.py", line 200, in Run
    op = serviceusage.BatchEnableApiCall(project, args.service)
         ^^^^^^^^^^^^^^^^^^^^^^^^^^^^^^^^^^^^^^^^^^^^^^^^^^^^^^
  File "/usr/bin/../lib/google-cloud-sdk/lib/googlecloudsdk/api_lib/services/serviceusage.py", line 698, in BatchEnableApiCall
    exceptions.ReraiseError(e,
  File "/usr/bin/../lib/google-cloud-sdk/lib/googlecloudsdk/api_lib/services/exceptions.py", line 158, in ReraiseError
    core_exceptions.reraise(klass(api_lib_exceptions.HttpException(err)))
  File "/usr/bin/../lib/google-cloud-sdk/lib/googlecloudsdk/core/exceptions.py", line 149, in reraise
    six.reraise(type(exc_value), exc_value, tb)
  File "/usr/bin/../lib/google-cloud-sdk/lib/third_party/six/__init__.py", line 718, in reraise
    raise value.with_traceback(tb)
  File "/usr/bin/../lib/google-cloud-sdk/lib/googlecloudsdk/api_lib/services/serviceusage.py", line 695, in BatchEnableApiCall
    return client.services.BatchEnable(request)
           ^^^^^^^^^^^^^^^^^^^^^^^^^^^^^^^^^^^^
  File "/usr/bin/../lib/google-cloud-sdk/lib/googlecloudsdk/generated_clients/apis/serviceusage/v1/serviceusage_v1_client.py", line 182, in BatchEnable
    return self._RunMethod(
           ^^^^^^^^^^^^^^^^
  File "/usr/bin/../lib/google-cloud-sdk/lib/third_party/apitools/base/py/base_api.py", line 747, in _RunMethod
    return self.ProcessHttpResponse(method_config, http_response, request)
           ^^^^^^^^^^^^^^^^^^^^^^^^^^^^^^^^^^^^^^^^^^^^^^^^^^^^^^^^^^^^^^^
  File "/usr/bin/../lib/google-cloud-sdk/lib/third_party/apitools/base/py/base_api.py", line 753, in ProcessHttpResponse
    self.__ProcessHttpResponse(method_config, http_response, request))
    ^^^^^^^^^^^^^^^^^^^^^^^^^^^^^^^^^^^^^^^^^^^^^^^^^^^^^^^^^^^^^^^^^
  File "/usr/bin/../lib/google-cloud-sdk/lib/third_party/apitools/base/py/base_api.py", line 612, in __ProcessHttpResponse
    raise exceptions.HttpError.FromResponse(
googlecloudsdk.api_lib.services.exceptions.EnableServicePermissionDeniedException: [jdiazderabago@gmail.com] does not have permission to access projects instance [proyectotest-1] (or it may not exist): Not found or permission denied for service(s):  cloudbuild.googleapis.com.
Help Token: AYJSUtllWNq0pi3pqHVwTZJvqGLdXto6DeLqY7kTSpxt2rCCwCuapye6l0QQEH0WL9E3WfYpSHAfsc0qW41B-7W-BKyi-gN9LCH_hhjm5WmFt-b0. This command is authenticated as jdiazderabago@gmail.com which is the active account specified by the [core/account] property
- '@type': type.googleapis.com/google.rpc.PreconditionFailure
  violations:
  - subject: ?error_code=220002&services=+cloudbuild.googleapis.com
    type: googleapis.com
- '@type': type.googleapis.com/google.rpc.ErrorInfo
  domain: serviceusage.googleapis.com
  metadata:
    services: ' cloudbuild.googleapis.com'
  reason: SERVICE_CONFIG_NOT_FOUND_OR_PERMISSION_DENIED
2024-11-04 15:54:26,656 ERROR    root            (gcloud.services.enable) [jdiazderabago@gmail.com] does not have permission to access projects instance [proyectotest-1] (or it may not exist): Not found or permission denied for service(s):  cloudbuild.googleapis.com.
Help Token: AYJSUtllWNq0pi3pqHVwTZJvqGLdXto6DeLqY7kTSpxt2rCCwCuapye6l0QQEH0WL9E3WfYpSHAfsc0qW41B-7W-BKyi-gN9LCH_hhjm5WmFt-b0. This command is authenticated as jdiazderabago@gmail.com which is the active account specified by the [core/account] property
- '@type': type.googleapis.com/google.rpc.PreconditionFailure
  violations:
  - subject: ?error_code=220002&services=+cloudbuild.googleapis.com
    type: googleapis.com
- '@type': type.googleapis.com/google.rpc.ErrorInfo
  domain: serviceusage.googleapis.com
  metadata:
    services: ' cloudbuild.googleapis.com'
  reason: SERVICE_CONFIG_NOT_FOUND_OR_PERMISSION_DENIED
